<?xml version="1.0" encoding="utf-8"?>
<!-- This URDF was automatically created by SolidWorks to URDF Exporter! Originally created by Stephen Brawner (brawner@gmail.com) 
     Commit Version: 1.6.0-4-g7f85cfe  Build Version: 1.6.7995.38578
     For more information, please see http://wiki.ros.org/sw_urdf_exporter -->
<robot
  name="tf_urdf3">
  <link
    name="base_link">
    <inertial>
      <origin
        xyz="-1.05559497177638E-12 6.31894336221611E-12 -5.17741961678007E-12"
        rpy="0 0 0" />
      <mass
        value="2.49683972846965" />
      <inertia
        ixx="0.00596159328883626"
        ixy="-5.06469082751166E-08"
        ixz="-1.5266709729098E-09"
        iyy="0.0122170913936761"
        iyz="-9.04363601046582E-06"
        izz="0.00670663028700821" />
    </inertial>
    <visual>
      <origin
        xyz="0 0 0"
        rpy="0 0 0" />
      <geometry>
        <mesh
          filename="package://tf_urdf3/meshes/base_link.STL" />
      </geometry>
      <material
        name="">
        <color
          rgba="0.752941176470588 0.752941176470588 0.752941176470588 1" />
      </material>
    </visual>
    <collision>
      <origin
        xyz="0 0 0"
        rpy="0 0 0" />
      <geometry>
        <mesh
          filename="package://tf_urdf3/meshes/base_link.STL" />
      </geometry>
    </collision>
  </link>
  <link
    name="base_scan">
    <inertial>
      <origin
        xyz="4.54497550705923E-16 0.00994901655834559 -4.16333634234434E-17"
        rpy="0 0 0" />
      <mass
        value="0.0660277715680958" />
      <inertia
        ixx="1.96156877893573E-05"
        ixy="-2.32345138020396E-22"
        ixz="-1.6940658945086E-21"
        iyy="3.48742138584865E-05"
        iyz="-1.68839275960928E-21"
        izz="1.96156117763069E-05" />
    </inertial>
    <visual>
      <origin
        xyz="0 0 0"
        rpy="0 0 0" />
      <geometry>
        <mesh
          filename="package://tf_urdf3/meshes/base_scan.STL" />
      </geometry>
      <material
        name="">
        <color
          rgba="0.792156862745098 0.819607843137255 0.933333333333333 1" />
      </material>
    </visual>
    <collision>
      <origin
        xyz="0 0 0"
        rpy="0 0 0" />
      <geometry>
        <mesh
          filename="package://tf_urdf3/meshes/base_scan.STL" />
      </geometry>
    </collision>
  </link>
  <joint
    name="scan_joint"
    type="revolute">
    <origin
      xyz="-0.00011198 0.067243 0.027941"
      rpy="1.5708 0 -2.6597" />
    <parent
      link="base_link" />
    <child
      link="base_scan" />
    <axis
      xyz="0 1 0" />
    <limit
      lower="0"
      upper="0"
      effort="0"
      velocity="0" />
  </joint>
  <link
    name="camera_link">
    <inertial>
      <origin
        xyz="-3.59644516483235E-06 -8.99346729618666E-05 -0.0199626938850732"
        rpy="0 0 0" />
      <mass
        value="0.182998721569065" />
      <inertia
        ixx="3.5992273850704E-05"
        ixy="2.02103200586128E-09"
        ixz="4.50591985459383E-08"
        iyy="0.000405203077313625"
        iyz="4.47034793272274E-08"
        izz="0.000396282426264132" />
    </inertial>
    <visual>
      <origin
        xyz="0 0 0"
        rpy="0 0 0" />
      <geometry>
        <mesh
          filename="package://tf_urdf3/meshes/camera_link.STL" />
      </geometry>
      <material
        name="">
        <color
          rgba="0.752941176470588 0.752941176470588 0.752941176470588 1" />
      </material>
    </visual>
    <collision>
      <origin
        xyz="0 0 0"
        rpy="0 0 0" />
      <geometry>
        <mesh
          filename="package://tf_urdf3/meshes/camera_link.STL" />
      </geometry>
    </collision>
  </link>
  <joint
    name="camera_joint"
    type="fixed">
    <origin
      xyz="-0.00011198 0.049243 0.081941"
      rpy="1.5708 0 -3.1416" />
    <parent
      link="base_link" />
    <child
      link="camera_link" />
    <axis
      xyz="0 0 0" />
  </joint>
  <link
    name="left_wheel_link">
    <inertial>
      <origin
        xyz="-0.0150496497452622 -1.96168775667971E-12 -1.66533453693773E-16"
        rpy="0 0 0" />
      <mass
        value="0.0895053073671552" />
      <inertia
        ixx="0.000104006422478187"
        ixy="7.89420250912323E-16"
        ixz="4.4681527755846E-20"
        iyy="5.80082032825446E-05"
        iyz="9.78363711660185E-16"
        izz="5.80082032677947E-05" />
    </inertial>
    <visual>
      <origin
        xyz="0 0 0"
        rpy="0 0 0" />
      <geometry>
        <mesh
          filename="package://tf_urdf3/meshes/left_wheel_link.STL" />
      </geometry>
      <material
        name="">
        <color
          rgba="0.250980392156863 0.250980392156863 0.250980392156863 1" />
      </material>
    </visual>
    <collision>
      <origin
        xyz="0 0 0"
        rpy="0 0 0" />
      <geometry>
        <mesh
          filename="package://tf_urdf3/meshes/left_wheel_link.STL" />
      </geometry>
    </collision>
  </link>
  <joint
    name="left_wheel_joint"
    type="continuous">
    <origin
      xyz="-0.15461 0.074993 -0.12206"
      rpy="0.84849 0 0" />
    <parent
      link="base_link" />
    <child
      link="left_wheel_link" />
    <axis
      xyz="1 0 0" />
  </joint>
  <link
    name="right_wheel_link">
    <inertial>
      <origin
        xyz="-0.0150496497452624 -1.96179184008827E-12 5.55111512312578E-17"
        rpy="0 0 0" />
      <mass
        value="0.0895053073671553" />
      <inertia
        ixx="0.000104006422478187"
        ixy="7.89519161283675E-16"
        ixz="-4.17738099496549E-20"
        iyy="5.80082032825446E-05"
        iyz="9.78345076935346E-16"
        izz="5.80082032677947E-05" />
    </inertial>
    <visual>
      <origin
        xyz="0 0 0"
        rpy="0 0 0" />
      <geometry>
        <mesh
          filename="package://tf_urdf3/meshes/right_wheel_link.STL" />
      </geometry>
      <material
        name="">
        <color
          rgba="0.250980392156863 0.250980392156863 0.250980392156863 1" />
      </material>
    </visual>
    <collision>
      <origin
        xyz="0 0 0"
        rpy="0 0 0" />
      <geometry>
        <mesh
          filename="package://tf_urdf3/meshes/right_wheel_link.STL" />
      </geometry>
    </collision>
  </link>
  <joint
    name="right_wheel_joint"
    type="continuous">
    <origin
      xyz="0.15439 0.074993 -0.12206"
      rpy="0.5371 0 3.1416" />
    <parent
      link="base_link" />
    <child
      link="right_wheel_link" />
    <axis
      xyz="1 0 0" />
  </joint>
  <link
    name="caster_link">
    <inertial>
      <origin
        xyz="0.00460335958615544 -2.77555756156289E-17 -2.77555756156289E-17"
        rpy="0 0 0" />
      <mass
        value="0.01152385226836" />
      <inertia
        ixx="2.43995864492354E-06"
        ixy="-1.54848210669927E-21"
        ixz="1.59997409983069E-21"
        iyy="1.40033256895839E-06"
        iyz="-1.05879118406788E-21"
        izz="1.40033256895839E-06" />
    </inertial>
    <visual>
      <origin
        xyz="0 0 0"
        rpy="0 0 0" />
      <geometry>
        <mesh
          filename="package://tf_urdf3/meshes/caster_link.STL" />
      </geometry>
      <material
        name="">
        <color
          rgba="1 1 1 1" />
      </material>
    </visual>
    <collision>
      <origin
        xyz="0 0 0"
        rpy="0 0 0" />
      <geometry>
        <mesh
          filename="package://tf_urdf3/meshes/caster_link.STL" />
      </geometry>
    </collision>
  </link>
  <joint
    name="caster_joint"
    type="continuous">
    <origin
      xyz="-0.0052945 -0.15459 -0.13706"
      rpy="3.1007 0 -0.034236" />
    <parent
      link="base_link" />
    <child
      link="caster_link" />
    <axis
      xyz="1 0 0" />
  </joint>
  <link
    name="arm_1_link">
    <inertial>
      <origin
        xyz="-0.00304007438065966 0.0196164335046979 -0.00291517433011433"
        rpy="0 0 0" />
      <mass
        value="0.102309676287535" />
      <inertia
        ixx="5.85277337608611E-05"
        ixy="-1.83034149314494E-07"
        ixz="-5.85534183281055E-07"
        iyy="0.000109918724976135"
        iyz="3.63049047084518E-07"
        izz="5.95682017970662E-05" />
    </inertial>
    <visual>
      <origin
        xyz="0 0 0"
        rpy="0 0 0" />
      <geometry>
        <mesh
          filename="package://tf_urdf3/meshes/arm_1_link.STL" />
      </geometry>
      <material
        name="">
        <color
          rgba="0.752941176470588 0.752941176470588 0.752941176470588 1" />
      </material>
    </visual>
    <collision>
      <origin
        xyz="0 0 0"
        rpy="0 0 0" />
      <geometry>
        <mesh
          filename="package://tf_urdf3/meshes/arm_1_link.STL" />
      </geometry>
    </collision>
  </link>
  <joint
    name="arm_1_joint"
    type="continuous">
    <origin
      xyz="-0.00011198 -0.0037567 0.15944"
      rpy="1.5708 0 1.9678" />
    <parent
      link="base_link" />
    <child
      link="arm_1_link" />
    <axis
      xyz="0 1 0" />
    <limit
      lower="-1.57"
      upper="1.57"
      effort="10"
      velocity="100" />
  </joint>
  <link
    name="arm_2_link">
    <inertial>
      <origin
        xyz="-0.00136241892687206 0.0760000000000048 0.0032497474917032"
        rpy="0 0 0" />
      <mass
        value="0.0731866074343535" />
      <inertia
        ixx="4.8007381560074E-05"
        ixy="-1.00851028373393E-08"
        ixz="8.91994561566121E-06"
        iyy="3.20760640864427E-05"
        iyz="2.40557713523583E-08"
        izz="3.04704178358833E-05" />
    </inertial>
    <visual>
      <origin
        xyz="0 0 0"
        rpy="0 0 0" />
      <geometry>
        <mesh
          filename="package://tf_urdf3/meshes/arm_2_link.STL" />
      </geometry>
      <material
        name="">
        <color
          rgba="0.752941176470588 0.752941176470588 0.752941176470588 1" />
      </material>
    </visual>
    <collision>
      <origin
        xyz="0 0 0"
        rpy="0 0 0" />
      <geometry>
        <mesh
          filename="package://tf_urdf3/meshes/arm_2_link.STL" />
      </geometry>
    </collision>
  </link>
  <joint
    name="arm_2_joint"
    type="continuous">
    <origin
      xyz="0.00057178 0.0325 0.00023971"
      rpy="0 0 0" />
    <parent
      link="arm_1_link" />
    <child
      link="arm_2_link" />
    <axis
      xyz="0.38664 0 -0.92223" />
    <limit
      lower="-1.57"
      upper="1.57"
      effort="10"
      velocity="100" />
  </joint>
  <link
    name="arm_3_link">
    <inertial>
      <origin
        xyz="-0.00258153228786722 0.0524015939542918 0.000939181170584955"
        rpy="0 0 0" />
      <mass
        value="0.103604281307373" />
      <inertia
        ixx="3.85881018738509E-05"
        ixy="-4.80398867236182E-07"
        ixz="5.05895931054935E-06"
        iyy="2.28862113904832E-05"
        iyz="-1.4445332566151E-07"
        izz="2.97794533691035E-05" />
    </inertial>
    <visual>
      <origin
        xyz="0 0 0"
        rpy="0 0 0" />
      <geometry>
        <mesh
          filename="package://tf_urdf3/meshes/arm_3_link.STL" />
      </geometry>
      <material
        name="">
        <color
          rgba="0.752941176470588 0.752941176470588 0.752941176470588 1" />
      </material>
    </visual>
    <collision>
      <origin
        xyz="0 0 0"
        rpy="0 0 0" />
      <geometry>
        <mesh
          filename="package://tf_urdf3/meshes/arm_3_link.STL" />
      </geometry>
    </collision>
  </link>
  <joint
    name="arm_3_joint"
    type="continuous">
    <origin
      xyz="0 0.152 0"
      rpy="0 0 0" />
    <parent
      link="arm_2_link" />
    <child
      link="arm_3_link" />
    <axis
      xyz="0.38664 0 -0.92223" />
    <limit
      lower="-1.57"
      upper="1.57"
      effort="10"
      velocity="100" />
  </joint>
  <link
    name="arm_4_link">
    <inertial>
      <origin
        xyz="-0.00101187424557146 0.0375011786161997 -0.00366708119504672"
        rpy="0 0 0" />
      <mass
        value="0.0995665365963181" />
      <inertia
        ixx="2.11129357501037E-05"
        ixy="-8.60509757749079E-08"
        ixz="2.61664433182042E-06"
        iyy="1.5114895217304E-05"
        iyz="-3.60758730665085E-08"
        izz="1.71059724055455E-05" />
    </inertial>
    <visual>
      <origin
        xyz="0 0 0"
        rpy="0 0 0" />
      <geometry>
        <mesh
          filename="package://tf_urdf3/meshes/arm_4_link.STL" />
      </geometry>
      <material
        name="">
        <color
          rgba="0.752941176470588 0.752941176470588 0.752941176470588 1" />
      </material>
    </visual>
    <collision>
      <origin
        xyz="0 0 0"
        rpy="0 0 0" />
      <geometry>
        <mesh
          filename="package://tf_urdf3/meshes/arm_4_link.STL" />
      </geometry>
    </collision>
  </link>
  <joint
    name="arm_4_joint"
    type="continuous">
    <origin
      xyz="0 0.1464 0"
      rpy="0 0 0" />
    <parent
      link="arm_3_link" />
    <child
      link="arm_4_link" />
    <axis
      xyz="0.38664 0 -0.92223" />
    <limit
      lower="-1.57"
      upper="1.57"
      effort="10"
      velocity="100" />
  </joint>
  <link
    name="arm_5_link">
    <inertial>
      <origin
        xyz="-0.00868940066499363 0.0276881875422991 -0.0253003256742447"
        rpy="0 0 0" />
      <mass
        value="0.0375612763588537" />
      <inertia
        ixx="6.51328883591069E-06"
        ixy="4.82424645923746E-09"
        ixz="1.70111532974492E-06"
        iyy="6.43248421285328E-06"
        iyz="-9.59387280153688E-09"
        izz="2.95122651270477E-06" />
    </inertial>
    <visual>
      <origin
        xyz="0 0 0"
        rpy="0 0 0" />
      <geometry>
        <mesh
          filename="package://tf_urdf3/meshes/arm_5_link.STL" />
      </geometry>
      <material
        name="">
        <color
          rgba="0.752941176470588 0.752941176470588 0.752941176470588 1" />
      </material>
    </visual>
    <collision>
      <origin
        xyz="0 0 0"
        rpy="0 0 0" />
      <geometry>
        <mesh
          filename="package://tf_urdf3/meshes/arm_5_link.STL" />
      </geometry>
    </collision>
  </link>
  <joint
    name="arm_5_joint"
    type="continuous">
    <origin
      xyz="0.00056091 0.09115 0.0028104"
      rpy="3.1416 0 3.1416" />
    <parent
      link="arm_4_link" />
    <child
      link="arm_5_link" />
    <axis
      xyz="0 1 0" />
    <limit
      lower="-1.57"
      upper="1.57"
      effort="10"
      velocity="100" />
  </joint>
  <link
    name="gripper_1_link">
    <inertial>
      <origin
        xyz="0.00016348046706538 -0.00403983489131265 0.00336463442621077"
        rpy="0 0 0" />
      <mass
        value="0.00233893532260202" />
      <inertia
        ixx="2.44085104510322E-07"
        ixy="-4.91339632043205E-09"
        ixz="-7.81436025649409E-19"
        iyy="7.71995240694166E-08"
        iyz="2.771416955401E-18"
        izz="3.18397565042682E-07" />
    </inertial>
    <visual>
      <origin
        xyz="0 0 0"
        rpy="0 0 0" />
      <geometry>
        <mesh
          filename="package://tf_urdf3/meshes/gripper_1_link.STL" />
      </geometry>
      <material
        name="">
        <color
          rgba="0.792156862745098 0.819607843137255 0.933333333333333 1" />
      </material>
    </visual>
    <collision>
      <origin
        xyz="0 0 0"
        rpy="0 0 0" />
      <geometry>
        <mesh
          filename="package://tf_urdf3/meshes/gripper_1_link.STL" />
      </geometry>
    </collision>
  </link>
  <joint
    name="gripper_1_joint"
    type="continuous">
    <origin
      xyz="0.0068104 0.0295 -0.011783"
      rpy="0.90777 -0.89161 2.1168" />
    <parent
      link="arm_5_link" />
    <child
      link="gripper_1_link" />
    <axis
      xyz="0 0 1" />
    <limit
      lower="-1.57"
      upper="1.57"
      effort="10"
      velocity="100" />
  </joint>
</robot>