<?xml version="1.0" encoding="utf-8"?>
<!-- This URDF was automatically created by SolidWorks to URDF Exporter! Originally created by Stephen Brawner (brawner@gmail.com) 
     Commit Version: 1.6.0-4-g7f85cfe  Build Version: 1.6.7995.38578
     For more information, please see http://wiki.ros.org/sw_urdf_exporter -->
<robot
  name="nav_tf_urdf">
  <link name="base_footprint"/>
  <joint name="base_joint" type="fixed">
    <parent link="base_footprint"/>
    <child link="base_link"/>
    <origin xyz="-1.05560534986818E-12 5.17741757590009E-12 6.3189360698697E-12" rpy="0 0 0" />
  </joint>
  <link
    name="base_link">
    <inertial>
      <origin
        xyz="-1.07955819150764E-12 3.98641248213828E-12 -8.16191932505118E-12"
        rpy="0 0 0" />
      <mass
        value="2.4556334802297" />
      <inertia
        ixx="0.00588389849656267"
        ixy="-5.54498496431469E-09"
        ixz="-1.53333170941911E-09"
        iyy="0.010210248943553"
        iyz="-6.09425077099926E-06"
        izz="0.00582594596712262" />
    </inertial>
    <visual>
      <origin
        xyz="0 0 0"
        rpy="0 0 0" />
      <geometry>
        <mesh
          filename="package://nav_tf_urdf/meshes/base_link.STL" />
      </geometry>
      <material
        name="">
        <color
          rgba="0.752941176470588 0.752941176470588 0.752941176470588 1" />
      </material>
    </visual>
    <collision>
      <origin
        xyz="0 0 0"
        rpy="0 0 0" />
      <geometry>
        <mesh
          filename="package://nav_tf_urdf/meshes/base_link.STL" />
      </geometry>
    </collision>
  </link>
  <link
    name="base_scan">
    <inertial>
      <origin
        xyz="-1.73472347597681E-18 -0.00994901655834558 2.72645823032617E-07"
        rpy="0 0 0" />
      <mass
        value="0.0660277715680958" />
      <inertia
        ixx="1.96156877893574E-05"
        ixy="-1.84238171772927E-21"
        ixz="-2.88695483567953E-24"
        iyy="3.48742138584865E-05"
        iyz="-1.95349716327188E-21"
        izz="1.96156117763069E-05" />
    </inertial>
    <visual>
      <origin
        xyz="0 0 0"
        rpy="0 0 0" />
      <geometry>
        <mesh
          filename="package://nav_tf_urdf/meshes/base_scan.STL" />
      </geometry>
      <material
        name="">
        <color
          rgba="0.792156862745098 0.819607843137255 0.933333333333333 1" />
      </material>
    </visual>
    <collision>
      <origin
        xyz="0 0 0"
        rpy="0 0 0" />
      <geometry>
        <mesh
          filename="package://nav_tf_urdf/meshes/base_scan.STL" />
      </geometry>
    </collision>
  </link>
  <joint
    name="scan_joint"
    type="continuous">
    <origin
      xyz="0 0.0120740335852946 0.0743670768316607"
      rpy="-1.5707963267949 0 -1.5707963267949" />
    <parent
      link="base_link" />
    <child
      link="base_scan" />
    <axis
      xyz="0 1 0" />
    <limit
      lower="0"
      upper="0"
      effort="0"
      velocity="0" />
  </joint>
  <link
    name="left_wheel_link">
    <inertial>
      <origin
        xyz="-0.0150471339237869 -1.947730171592E-12 8.32667268468867E-17"
        rpy="0 0 0" />
      <mass
        value="0.0901982674382036" />
      <inertia
        ixx="0.000104914037889676"
        ixy="7.89015853905989E-16"
        ixz="1.05084195132732E-19"
        iyy="5.86007633745242E-05"
        iyz="9.7832750100169E-16"
        izz="5.86007633597741E-05" />
    </inertial>
    <visual>
      <origin
        xyz="0 0 0"
        rpy="0 0 0" />
      <geometry>
        <mesh
          filename="package://nav_tf_urdf/meshes/left_wheel_link.STL" />
      </geometry>
      <material
        name="">
        <color
          rgba="0.250980392156863 0.250980392156863 0.250980392156863 1" />
      </material>
    </visual>
    <collision>
      <origin
        xyz="0 0 0"
        rpy="0 0 0" />
      <geometry>
        <mesh
          filename="package://nav_tf_urdf/meshes/left_wheel_link.STL" />
      </geometry>
    </collision>
  </link>
  <joint
    name="left_wheel_joint"
    type="continuous">
    <origin
      xyz="-0.154499727354178 0.0198240335852944 -0.0756329231683387"
      rpy="0.037411098547317 0 0" />
    <parent
      link="base_link" />
    <child
      link="left_wheel_link" />
    <axis
      xyz="1 0 0" />
  </joint>
  <link
    name="right_wheel_link">
    <inertial>
      <origin
        xyz="-0.0150471339237868 -1.94670668474117E-12 -2.15105711021124E-16"
        rpy="0 0 0" />
      <mass
        value="0.0901982674382035" />
      <inertia
        ixx="0.000104914037889676"
        ixy="7.88953684741619E-16"
        ixz="2.6904953114311E-19"
        iyy="5.86007633745242E-05"
        iyz="9.78323054078717E-16"
        izz="5.86007633597741E-05" />
    </inertial>
    <visual>
      <origin
        xyz="0 0 0"
        rpy="0 0 0" />
      <geometry>
        <mesh
          filename="package://nav_tf_urdf/meshes/right_wheel_link.STL" />
      </geometry>
      <material
        name="">
        <color
          rgba="0.250980392156863 0.250980392156863 0.250980392156863 1" />
      </material>
    </visual>
    <collision>
      <origin
        xyz="0 0 0"
        rpy="0 0 0" />
      <geometry>
        <mesh
          filename="package://nav_tf_urdf/meshes/right_wheel_link.STL" />
      </geometry>
    </collision>
  </link>
  <joint
    name="right_wheel_joint"
    type="continuous">
    <origin
      xyz="0.154500272645823 0.0198240335852952 -0.075632923168337"
      rpy="-1.77866827099237 0 3.14159265358979" />
    <parent
      link="base_link" />
    <child
      link="right_wheel_link" />
    <axis
      xyz="1 0 0" />
  </joint>
  <link
    name="caster_link">
    <inertial>
      <origin
        xyz="0.00660393903079727 0 -4.16333634234434E-17"
        rpy="0 0 0" />
      <mass
        value="0.01152385226836" />
      <inertia
        ixx="2.43995864492354E-06"
        ixy="-1.60142166590266E-21"
        ixz="1.6448486480617E-21"
        iyy="1.40033256895839E-06"
        iyz="-9.72764400362361E-22"
        izz="1.40033256895838E-06" />
    </inertial>
    <visual>
      <origin
        xyz="0 0 0"
        rpy="0 0 0" />
      <geometry>
        <mesh
          filename="package://nav_tf_urdf/meshes/caster_link.STL" />
      </geometry>
      <material
        name="">
        <color
          rgba="1 1 1 1" />
      </material>
    </visual>
    <collision>
      <origin
        xyz="0 0 0"
        rpy="0 0 0" />
      <geometry>
        <mesh
          filename="package://nav_tf_urdf/meshes/caster_link.STL" />
      </geometry>
    </collision>
  </link>
  <joint
    name="caster_joint"
    type="continuous">
    <origin
      xyz="-0.00718168989947332 -0.20968995832357 -0.0906329231683387"
      rpy="-3.06614609532378 0 -0.0342357063287251" />
    <parent
      link="base_link" />
    <child
      link="caster_link" />
    <axis
      xyz="1 0 0" />
  </joint>
</robot>